# Generated by Django 5.1.6 on 2025-05-15 11:14

from django.db import migrations, models


class Migration(migrations.Migration):

    dependencies = [
        ('base', '0003_alter_exceptiontrace_error_message_and_more'),
    ]

    operations = [
        migrations.AddField(
            model_name='category',
            name='deleted_at',
            field=models.DateTimeField(blank=True, null=True),
        ),
        migrations.AddField(
            model_name='contact',
            name='deleted_at',
            field=models.DateTimeField(blank=True, null=True),
        ),
        migrations.AddField(
            model_name='skill',
            name='deleted_at',
            field=models.DateTimeField(blank=True, null=True),
        ),
        migrations.AddField(
            model_name='tags',
            name='deleted_at',
            field=models.DateTimeField(blank=True, null=True),
        ),
    ]
